<?xml version="1.0"?>
<robot  name="rope" >
 <link  name="link0" >
  <inertial >
   <mass  value="0.012499999999999999" />
   <origin  xyz="0.0 0.0 0.0" />
  </inertial>
  <visual >
   <geometry >
    <cylinder  length="0"  radius="0" />
   </geometry>
   <origin  xyz="0.0 0.0 0.0" />
  </visual>
  <collision >
   <geometry >
    <cylinder  length="0"  radius="0" />
   </geometry>
   <origin  xyz="0.0 0.0 0.0" />
  </collision>
 </link>
 <link  name="link1" >
  <inertial >
   <mass  value="0.012499999999999999" />
   <origin  xyz="0.0 0.0 0.020833333333333332" />
  </inertial>
  <visual >
   <geometry >
    <cylinder  length="0.041666666666666664"  radius="0.02" />
   </geometry>
   <origin  xyz="0.0 0.0 0.020833333333333332" />
  </visual>
  <collision >
   <geometry >
    <cylinder  length="0.041666666666666664"  radius="0.02" />
   </geometry>
   <origin  xyz="0.0 0.0 0.020833333333333332" />
  </collision>
 </link>
 <link  name="link2" >
  <inertial >
   <mass  value="0.012499999999999999" />
   <origin  xyz="0.0 0.0 0.0" />
  </inertial>
  <visual >
   <geometry >
    <cylinder  length="0"  radius="0" />
   </geometry>
   <origin  xyz="0.0 0.0 0.0" />
  </visual>
  <collision >
   <geometry >
    <cylinder  length="0"  radius="0" />
   </geometry>
   <origin  xyz="0.0 0.0 0.0" />
  </collision>
 </link>
 <link  name="link3" >
  <inertial >
   <mass  value="0.012499999999999999" />
   <origin  xyz="0.0 0.0 0.020833333333333332" />
  </inertial>
  <visual >
   <geometry >
    <cylinder  length="0.041666666666666664"  radius="0.02" />
   </geometry>
   <origin  xyz="0.0 0.0 0.020833333333333332" />
  </visual>
  <collision >
   <geometry >
    <cylinder  length="0.041666666666666664"  radius="0.02" />
   </geometry>
   <origin  xyz="0.0 0.0 0.020833333333333332" />
  </collision>
 </link>
 <link  name="link4" >
  <inertial >
   <mass  value="0.012499999999999999" />
   <origin  xyz="0.0 0.0 0.0" />
  </inertial>
  <visual >
   <geometry >
    <cylinder  length="0"  radius="0" />
   </geometry>
   <origin  xyz="0.0 0.0 0.0" />
  </visual>
  <collision >
   <geometry >
    <cylinder  length="0"  radius="0" />
   </geometry>
   <origin  xyz="0.0 0.0 0.0" />
  </collision>
 </link>
 <link  name="link5" >
  <inertial >
   <mass  value="0.012499999999999999" />
   <origin  xyz="0.0 0.0 0.020833333333333332" />
  </inertial>
  <visual >
   <geometry >
    <cylinder  length="0.041666666666666664"  radius="0.02" />
   </geometry>
   <origin  xyz="0.0 0.0 0.020833333333333332" />
  </visual>
  <collision >
   <geometry >
    <cylinder  length="0.041666666666666664"  radius="0.02" />
   </geometry>
   <origin  xyz="0.0 0.0 0.020833333333333332" />
  </collision>
 </link>
 <link  name="link6" >
  <inertial >
   <mass  value="0.012499999999999999" />
   <origin  xyz="0.0 0.0 0.0" />
  </inertial>
  <visual >
   <geometry >
    <cylinder  length="0"  radius="0" />
   </geometry>
   <origin  xyz="0.0 0.0 0.0" />
  </visual>
  <collision >
   <geometry >
    <cylinder  length="0"  radius="0" />
   </geometry>
   <origin  xyz="0.0 0.0 0.0" />
  </collision>
 </link>
 <link  name="link7" >
  <inertial >
   <mass  value="0.012499999999999999" />
   <origin  xyz="0.0 0.0 0.020833333333333332" />
  </inertial>
  <visual >
   <geometry >
    <cylinder  length="0.041666666666666664"  radius="0.02" />
   </geometry>
   <origin  xyz="0.0 0.0 0.020833333333333332" />
  </visual>
  <collision >
   <geometry >
    <cylinder  length="0.041666666666666664"  radius="0.02" />
   </geometry>
   <origin  xyz="0.0 0.0 0.020833333333333332" />
  </collision>
 </link>
 <link  name="link8" >
  <inertial >
   <mass  value="0.012499999999999999" />
   <origin  xyz="0.0 0.0 0.0" />
  </inertial>
  <visual >
   <geometry >
    <cylinder  length="0"  radius="0" />
   </geometry>
   <origin  xyz="0.0 0.0 0.0" />
  </visual>
  <collision >
   <geometry >
    <cylinder  length="0"  radius="0" />
   </geometry>
   <origin  xyz="0.0 0.0 0.0" />
  </collision>
 </link>
 <link  name="link9" >
  <inertial >
   <mass  value="0.012499999999999999" />
   <origin  xyz="0.0 0.0 0.020833333333333332" />
  </inertial>
  <visual >
   <geometry >
    <cylinder  length="0.041666666666666664"  radius="0.02" />
   </geometry>
   <origin  xyz="0.0 0.0 0.020833333333333332" />
  </visual>
  <collision >
   <geometry >
    <cylinder  length="0.041666666666666664"  radius="0.02" />
   </geometry>
   <origin  xyz="0.0 0.0 0.020833333333333332" />
  </collision>
 </link>
 <link  name="link10" >
  <inertial >
   <mass  value="0.012499999999999999" />
   <origin  xyz="0.0 0.0 0.0" />
  </inertial>
  <visual >
   <geometry >
    <cylinder  length="0"  radius="0" />
   </geometry>
   <origin  xyz="0.0 0.0 0.0" />
  </visual>
  <collision >
   <geometry >
    <cylinder  length="0"  radius="0" />
   </geometry>
   <origin  xyz="0.0 0.0 0.0" />
  </collision>
 </link>
 <link  name="link11" >
  <inertial >
   <mass  value="0.012499999999999999" />
   <origin  xyz="0.0 0.0 0.020833333333333332" />
  </inertial>
  <visual >
   <geometry >
    <cylinder  length="0.041666666666666664"  radius="0.02" />
   </geometry>
   <origin  xyz="0.0 0.0 0.020833333333333332" />
  </visual>
  <collision >
   <geometry >
    <cylinder  length="0.041666666666666664"  radius="0.02" />
   </geometry>
   <origin  xyz="0.0 0.0 0.020833333333333332" />
  </collision>
 </link>
 <link  name="link12" >
  <inertial >
   <mass  value="0.012499999999999999" />
   <origin  xyz="0.0 0.0 0.0" />
  </inertial>
  <visual >
   <geometry >
    <cylinder  length="0"  radius="0" />
   </geometry>
   <origin  xyz="0.0 0.0 0.0" />
  </visual>
  <collision >
   <geometry >
    <cylinder  length="0"  radius="0" />
   </geometry>
   <origin  xyz="0.0 0.0 0.0" />
  </collision>
 </link>
 <link  name="link13" >
  <inertial >
   <mass  value="0.012499999999999999" />
   <origin  xyz="0.0 0.0 0.020833333333333332" />
  </inertial>
  <visual >
   <geometry >
    <cylinder  length="0.041666666666666664"  radius="0.02" />
   </geometry>
   <origin  xyz="0.0 0.0 0.020833333333333332" />
  </visual>
  <collision >
   <geometry >
    <cylinder  length="0.041666666666666664"  radius="0.02" />
   </geometry>
   <origin  xyz="0.0 0.0 0.020833333333333332" />
  </collision>
 </link>
 <link  name="link14" >
  <inertial >
   <mass  value="0.012499999999999999" />
   <origin  xyz="0.0 0.0 0.0" />
  </inertial>
  <visual >
   <geometry >
    <cylinder  length="0"  radius="0" />
   </geometry>
   <origin  xyz="0.0 0.0 0.0" />
  </visual>
  <collision >
   <geometry >
    <cylinder  length="0"  radius="0" />
   </geometry>
   <origin  xyz="0.0 0.0 0.0" />
  </collision>
 </link>
 <link  name="link15" >
  <inertial >
   <mass  value="0.012499999999999999" />
   <origin  xyz="0.0 0.0 0.020833333333333332" />
  </inertial>
  <visual >
   <geometry >
    <cylinder  length="0.041666666666666664"  radius="0.02" />
   </geometry>
   <origin  xyz="0.0 0.0 0.020833333333333332" />
  </visual>
  <collision >
   <geometry >
    <cylinder  length="0.041666666666666664"  radius="0.02" />
   </geometry>
   <origin  xyz="0.0 0.0 0.020833333333333332" />
  </collision>
 </link>
 <link  name="link16" >
  <inertial >
   <mass  value="0.012499999999999999" />
   <origin  xyz="0.0 0.0 0.0" />
  </inertial>
  <visual >
   <geometry >
    <cylinder  length="0"  radius="0" />
   </geometry>
   <origin  xyz="0.0 0.0 0.0" />
  </visual>
  <collision >
   <geometry >
    <cylinder  length="0"  radius="0" />
   </geometry>
   <origin  xyz="0.0 0.0 0.0" />
  </collision>
 </link>
 <link  name="link17" >
  <inertial >
   <mass  value="0.012499999999999999" />
   <origin  xyz="0.0 0.0 0.020833333333333332" />
  </inertial>
  <visual >
   <geometry >
    <cylinder  length="0.041666666666666664"  radius="0.02" />
   </geometry>
   <origin  xyz="0.0 0.0 0.020833333333333332" />
  </visual>
  <collision >
   <geometry >
    <cylinder  length="0.041666666666666664"  radius="0.02" />
   </geometry>
   <origin  xyz="0.0 0.0 0.020833333333333332" />
  </collision>
 </link>
 <link  name="link18" >
  <inertial >
   <mass  value="0.012499999999999999" />
   <origin  xyz="0.0 0.0 0.0" />
  </inertial>
  <visual >
   <geometry >
    <cylinder  length="0"  radius="0" />
   </geometry>
   <origin  xyz="0.0 0.0 0.0" />
  </visual>
  <collision >
   <geometry >
    <cylinder  length="0"  radius="0" />
   </geometry>
   <origin  xyz="0.0 0.0 0.0" />
  </collision>
 </link>
 <link  name="link19" >
  <inertial >
   <mass  value="0.012499999999999999" />
   <origin  xyz="0.0 0.0 0.020833333333333332" />
  </inertial>
  <visual >
   <geometry >
    <cylinder  length="0.041666666666666664"  radius="0.02" />
   </geometry>
   <origin  xyz="0.0 0.0 0.020833333333333332" />
  </visual>
  <collision >
   <geometry >
    <cylinder  length="0.041666666666666664"  radius="0.02" />
   </geometry>
   <origin  xyz="0.0 0.0 0.020833333333333332" />
  </collision>
 </link>
 <link  name="link20" >
  <inertial >
   <mass  value="0.012499999999999999" />
   <origin  xyz="0.0 0.0 0.0" />
  </inertial>
  <visual >
   <geometry >
    <cylinder  length="0"  radius="0" />
   </geometry>
   <origin  xyz="0.0 0.0 0.0" />
  </visual>
  <collision >
   <geometry >
    <cylinder  length="0"  radius="0" />
   </geometry>
   <origin  xyz="0.0 0.0 0.0" />
  </collision>
 </link>
 <link  name="link21" >
  <inertial >
   <mass  value="0.012499999999999999" />
   <origin  xyz="0.0 0.0 0.020833333333333332" />
  </inertial>
  <visual >
   <geometry >
    <cylinder  length="0.041666666666666664"  radius="0.02" />
   </geometry>
   <origin  xyz="0.0 0.0 0.020833333333333332" />
  </visual>
  <collision >
   <geometry >
    <cylinder  length="0.041666666666666664"  radius="0.02" />
   </geometry>
   <origin  xyz="0.0 0.0 0.020833333333333332" />
  </collision>
 </link>
 <link  name="link22" >
  <inertial >
   <mass  value="0.012499999999999999" />
   <origin  xyz="0.0 0.0 0.0" />
  </inertial>
  <visual >
   <geometry >
    <cylinder  length="0"  radius="0" />
   </geometry>
   <origin  xyz="0.0 0.0 0.0" />
  </visual>
  <collision >
   <geometry >
    <cylinder  length="0"  radius="0" />
   </geometry>
   <origin  xyz="0.0 0.0 0.0" />
  </collision>
 </link>
 <link  name="link23" >
  <inertial >
   <mass  value="0.012499999999999999" />
   <origin  xyz="0.0 0.0 0.020833333333333332" />
  </inertial>
  <visual >
   <geometry >
    <cylinder  length="0.041666666666666664"  radius="0.02" />
   </geometry>
   <origin  xyz="0.0 0.0 0.020833333333333332" />
  </visual>
  <collision >
   <geometry >
    <cylinder  length="0.041666666666666664"  radius="0.02" />
   </geometry>
   <origin  xyz="0.0 0.0 0.020833333333333332" />
  </collision>
 </link>
 <link  name="link24" >
  <inertial >
   <mass  value="0.012499999999999999" />
   <origin  xyz="0.0 0.0 0.0" />
  </inertial>
  <visual >
   <geometry >
    <cylinder  length="0"  radius="0" />
   </geometry>
   <origin  xyz="0.0 0.0 0.0" />
  </visual>
  <collision >
   <geometry >
    <cylinder  length="0"  radius="0" />
   </geometry>
   <origin  xyz="0.0 0.0 0.0" />
  </collision>
 </link>
 <link  name="link25" >
  <inertial >
   <mass  value="0.012499999999999999" />
   <origin  xyz="0.0 0.0 0.020833333333333332" />
  </inertial>
  <visual >
   <geometry >
    <cylinder  length="0.041666666666666664"  radius="0.02" />
   </geometry>
   <origin  xyz="0.0 0.0 0.020833333333333332" />
  </visual>
  <collision >
   <geometry >
    <cylinder  length="0.041666666666666664"  radius="0.02" />
   </geometry>
   <origin  xyz="0.0 0.0 0.020833333333333332" />
  </collision>
 </link>
 <link  name="link26" >
  <inertial >
   <mass  value="0.012499999999999999" />
   <origin  xyz="0.0 0.0 0.0" />
  </inertial>
  <visual >
   <geometry >
    <cylinder  length="0"  radius="0" />
   </geometry>
   <origin  xyz="0.0 0.0 0.0" />
  </visual>
  <collision >
   <geometry >
    <cylinder  length="0"  radius="0" />
   </geometry>
   <origin  xyz="0.0 0.0 0.0" />
  </collision>
 </link>
 <link  name="link27" >
  <inertial >
   <mass  value="0.012499999999999999" />
   <origin  xyz="0.0 0.0 0.020833333333333332" />
  </inertial>
  <visual >
   <geometry >
    <cylinder  length="0.041666666666666664"  radius="0.02" />
   </geometry>
   <origin  xyz="0.0 0.0 0.020833333333333332" />
  </visual>
  <collision >
   <geometry >
    <cylinder  length="0.041666666666666664"  radius="0.02" />
   </geometry>
   <origin  xyz="0.0 0.0 0.020833333333333332" />
  </collision>
 </link>
 <link  name="link28" >
  <inertial >
   <mass  value="0.012499999999999999" />
   <origin  xyz="0.0 0.0 0.0" />
  </inertial>
  <visual >
   <geometry >
    <cylinder  length="0"  radius="0" />
   </geometry>
   <origin  xyz="0.0 0.0 0.0" />
  </visual>
  <collision >
   <geometry >
    <cylinder  length="0"  radius="0" />
   </geometry>
   <origin  xyz="0.0 0.0 0.0" />
  </collision>
 </link>
 <link  name="link29" >
  <inertial >
   <mass  value="0.012499999999999999" />
   <origin  xyz="0.0 0.0 0.020833333333333332" />
  </inertial>
  <visual >
   <geometry >
    <cylinder  length="0.041666666666666664"  radius="0.02" />
   </geometry>
   <origin  xyz="0.0 0.0 0.020833333333333332" />
  </visual>
  <collision >
   <geometry >
    <cylinder  length="0.041666666666666664"  radius="0.02" />
   </geometry>
   <origin  xyz="0.0 0.0 0.020833333333333332" />
  </collision>
 </link>
 <link  name="link30" >
  <inertial >
   <mass  value="0.012499999999999999" />
   <origin  xyz="0.0 0.0 0.0" />
  </inertial>
  <visual >
   <geometry >
    <cylinder  length="0"  radius="0" />
   </geometry>
   <origin  xyz="0.0 0.0 0.0" />
  </visual>
  <collision >
   <geometry >
    <cylinder  length="0"  radius="0" />
   </geometry>
   <origin  xyz="0.0 0.0 0.0" />
  </collision>
 </link>
 <link  name="link31" >
  <inertial >
   <mass  value="0.012499999999999999" />
   <origin  xyz="0.0 0.0 0.020833333333333332" />
  </inertial>
  <visual >
   <geometry >
    <cylinder  length="0.041666666666666664"  radius="0.02" />
   </geometry>
   <origin  xyz="0.0 0.0 0.020833333333333332" />
  </visual>
  <collision >
   <geometry >
    <cylinder  length="0.041666666666666664"  radius="0.02" />
   </geometry>
   <origin  xyz="0.0 0.0 0.020833333333333332" />
  </collision>
 </link>
 <link  name="link32" >
  <inertial >
   <mass  value="0.012499999999999999" />
   <origin  xyz="0.0 0.0 0.0" />
  </inertial>
  <visual >
   <geometry >
    <cylinder  length="0"  radius="0" />
   </geometry>
   <origin  xyz="0.0 0.0 0.0" />
  </visual>
  <collision >
   <geometry >
    <cylinder  length="0"  radius="0" />
   </geometry>
   <origin  xyz="0.0 0.0 0.0" />
  </collision>
 </link>
 <link  name="link33" >
  <inertial >
   <mass  value="0.012499999999999999" />
   <origin  xyz="0.0 0.0 0.020833333333333332" />
  </inertial>
  <visual >
   <geometry >
    <cylinder  length="0.041666666666666664"  radius="0.02" />
   </geometry>
   <origin  xyz="0.0 0.0 0.020833333333333332" />
  </visual>
  <collision >
   <geometry >
    <cylinder  length="0.041666666666666664"  radius="0.02" />
   </geometry>
   <origin  xyz="0.0 0.0 0.020833333333333332" />
  </collision>
 </link>
 <link  name="link34" >
  <inertial >
   <mass  value="0.012499999999999999" />
   <origin  xyz="0.0 0.0 0.0" />
  </inertial>
  <visual >
   <geometry >
    <cylinder  length="0"  radius="0" />
   </geometry>
   <origin  xyz="0.0 0.0 0.0" />
  </visual>
  <collision >
   <geometry >
    <cylinder  length="0"  radius="0" />
   </geometry>
   <origin  xyz="0.0 0.0 0.0" />
  </collision>
 </link>
 <link  name="link35" >
  <inertial >
   <mass  value="0.012499999999999999" />
   <origin  xyz="0.0 0.0 0.020833333333333332" />
  </inertial>
  <visual >
   <geometry >
    <cylinder  length="0.041666666666666664"  radius="0.02" />
   </geometry>
   <origin  xyz="0.0 0.0 0.020833333333333332" />
  </visual>
  <collision >
   <geometry >
    <cylinder  length="0.041666666666666664"  radius="0.02" />
   </geometry>
   <origin  xyz="0.0 0.0 0.020833333333333332" />
  </collision>
 </link>
 <link  name="link36" >
  <inertial >
   <mass  value="0.012499999999999999" />
   <origin  xyz="0.0 0.0 0.0" />
  </inertial>
  <visual >
   <geometry >
    <cylinder  length="0"  radius="0" />
   </geometry>
   <origin  xyz="0.0 0.0 0.0" />
  </visual>
  <collision >
   <geometry >
    <cylinder  length="0"  radius="0" />
   </geometry>
   <origin  xyz="0.0 0.0 0.0" />
  </collision>
 </link>
 <link  name="link37" >
  <inertial >
   <mass  value="0.012499999999999999" />
   <origin  xyz="0.0 0.0 0.020833333333333332" />
  </inertial>
  <visual >
   <geometry >
    <cylinder  length="0.041666666666666664"  radius="0.02" />
   </geometry>
   <origin  xyz="0.0 0.0 0.020833333333333332" />
  </visual>
  <collision >
   <geometry >
    <cylinder  length="0.041666666666666664"  radius="0.02" />
   </geometry>
   <origin  xyz="0.0 0.0 0.020833333333333332" />
  </collision>
 </link>
 <link  name="link38" >
  <inertial >
   <mass  value="0.012499999999999999" />
   <origin  xyz="0.0 0.0 0.0" />
  </inertial>
  <visual >
   <geometry >
    <cylinder  length="0"  radius="0" />
   </geometry>
   <origin  xyz="0.0 0.0 0.0" />
  </visual>
  <collision >
   <geometry >
    <cylinder  length="0"  radius="0" />
   </geometry>
   <origin  xyz="0.0 0.0 0.0" />
  </collision>
 </link>
 <link  name="link39" >
  <inertial >
   <mass  value="0.012499999999999999" />
   <origin  xyz="0.0 0.0 0.020833333333333332" />
  </inertial>
  <visual >
   <geometry >
    <cylinder  length="0.041666666666666664"  radius="0.02" />
   </geometry>
   <origin  xyz="0.0 0.0 0.020833333333333332" />
  </visual>
  <collision >
   <geometry >
    <cylinder  length="0.041666666666666664"  radius="0.02" />
   </geometry>
   <origin  xyz="0.0 0.0 0.020833333333333332" />
  </collision>
 </link>
 <link  name="link40" >
  <inertial >
   <mass  value="0.012499999999999999" />
   <origin  xyz="0.0 0.0 0.0" />
  </inertial>
  <visual >
   <geometry >
    <cylinder  length="0"  radius="0" />
   </geometry>
   <origin  xyz="0.0 0.0 0.0" />
  </visual>
  <collision >
   <geometry >
    <cylinder  length="0"  radius="0" />
   </geometry>
   <origin  xyz="0.0 0.0 0.0" />
  </collision>
 </link>
 <link  name="link41" >
  <inertial >
   <mass  value="0.012499999999999999" />
   <origin  xyz="0.0 0.0 0.020833333333333332" />
  </inertial>
  <visual >
   <geometry >
    <cylinder  length="0.041666666666666664"  radius="0.02" />
   </geometry>
   <origin  xyz="0.0 0.0 0.020833333333333332" />
  </visual>
  <collision >
   <geometry >
    <cylinder  length="0.041666666666666664"  radius="0.02" />
   </geometry>
   <origin  xyz="0.0 0.0 0.020833333333333332" />
  </collision>
 </link>
 <link  name="link42" >
  <inertial >
   <mass  value="0.012499999999999999" />
   <origin  xyz="0.0 0.0 0.0" />
  </inertial>
  <visual >
   <geometry >
    <cylinder  length="0"  radius="0" />
   </geometry>
   <origin  xyz="0.0 0.0 0.0" />
  </visual>
  <collision >
   <geometry >
    <cylinder  length="0"  radius="0" />
   </geometry>
   <origin  xyz="0.0 0.0 0.0" />
  </collision>
 </link>
 <link  name="link43" >
  <inertial >
   <mass  value="0.012499999999999999" />
   <origin  xyz="0.0 0.0 0.020833333333333332" />
  </inertial>
  <visual >
   <geometry >
    <cylinder  length="0.041666666666666664"  radius="0.02" />
   </geometry>
   <origin  xyz="0.0 0.0 0.020833333333333332" />
  </visual>
  <collision >
   <geometry >
    <cylinder  length="0.041666666666666664"  radius="0.02" />
   </geometry>
   <origin  xyz="0.0 0.0 0.020833333333333332" />
  </collision>
 </link>
 <link  name="link44" >
  <inertial >
   <mass  value="0.012499999999999999" />
   <origin  xyz="0.0 0.0 0.0" />
  </inertial>
  <visual >
   <geometry >
    <cylinder  length="0"  radius="0" />
   </geometry>
   <origin  xyz="0.0 0.0 0.0" />
  </visual>
  <collision >
   <geometry >
    <cylinder  length="0"  radius="0" />
   </geometry>
   <origin  xyz="0.0 0.0 0.0" />
  </collision>
 </link>
 <link  name="link45" >
  <inertial >
   <mass  value="0.012499999999999999" />
   <origin  xyz="0.0 0.0 0.020833333333333332" />
  </inertial>
  <visual >
   <geometry >
    <cylinder  length="0.041666666666666664"  radius="0.02" />
   </geometry>
   <origin  xyz="0.0 0.0 0.020833333333333332" />
  </visual>
  <collision >
   <geometry >
    <cylinder  length="0.041666666666666664"  radius="0.02" />
   </geometry>
   <origin  xyz="0.0 0.0 0.020833333333333332" />
  </collision>
 </link>
 <link  name="link46" >
  <inertial >
   <mass  value="0.012499999999999999" />
   <origin  xyz="0.0 0.0 0.0" />
  </inertial>
  <visual >
   <geometry >
    <cylinder  length="0"  radius="0" />
   </geometry>
   <origin  xyz="0.0 0.0 0.0" />
  </visual>
  <collision >
   <geometry >
    <cylinder  length="0"  radius="0" />
   </geometry>
   <origin  xyz="0.0 0.0 0.0" />
  </collision>
 </link>
 <link  name="link47" >
  <inertial >
   <mass  value="0.012499999999999999" />
   <origin  xyz="0.0 0.0 0.020833333333333332" />
  </inertial>
  <visual >
   <geometry >
    <cylinder  length="0.041666666666666664"  radius="0.02" />
   </geometry>
   <origin  xyz="0.0 0.0 0.020833333333333332" />
  </visual>
  <collision >
   <geometry >
    <cylinder  length="0.041666666666666664"  radius="0.02" />
   </geometry>
   <origin  xyz="0.0 0.0 0.020833333333333332" />
  </collision>
 </link>
 <joint  type="revolute"  name="joint0" >
  <parent  link="panda_hand" />
  <child  link="link0" />
  <dynamics  damping="0.0" />
  <limit  upper="2.5"  lower="-2.5"  effort="20"  velocity="20" />
  <axis  xyz="0 1 0" />
  <origin  xyz="0.0 0.0 0" />
 </joint>
 <joint  type="revolute"  name="joint1" >
  <parent  link="link0" />
  <child  link="link1" />
  <dynamics  damping="0.0" />
  <limit  upper="2.5"  lower="-2.5"  effort="20"  velocity="20" />
  <axis  xyz="1 0 0" />
  <origin  xyz="0.0 0.0 0" />
 </joint>
 <joint  type="revolute"  name="joint2" >
  <parent  link="link1" />
  <child  link="link2" />
  <dynamics  damping="0.0" />
  <limit  upper="2.5"  lower="-2.5"  effort="20"  velocity="20" />
  <axis  xyz="0 1 0" />
  <origin  xyz="0.0 0.0 0.041666666666666664" />
 </joint>
 <joint  type="revolute"  name="joint3" >
  <parent  link="link2" />
  <child  link="link3" />
  <dynamics  damping="0.0" />
  <limit  upper="2.5"  lower="-2.5"  effort="20"  velocity="20" />
  <axis  xyz="1 0 0" />
  <origin  xyz="0.0 0.0 0" />
 </joint>
 <joint  type="revolute"  name="joint4" >
  <parent  link="link3" />
  <child  link="link4" />
  <dynamics  damping="0.0" />
  <limit  upper="2.5"  lower="-2.5"  effort="20"  velocity="20" />
  <axis  xyz="0 1 0" />
  <origin  xyz="0.0 0.0 0.041666666666666664" />
 </joint>
 <joint  type="revolute"  name="joint5" >
  <parent  link="link4" />
  <child  link="link5" />
  <dynamics  damping="0.0" />
  <limit  upper="2.5"  lower="-2.5"  effort="20"  velocity="20" />
  <axis  xyz="1 0 0" />
  <origin  xyz="0.0 0.0 0" />
 </joint>
 <joint  type="revolute"  name="joint6" >
  <parent  link="link5" />
  <child  link="link6" />
  <dynamics  damping="0.0" />
  <limit  upper="2.5"  lower="-2.5"  effort="20"  velocity="20" />
  <axis  xyz="0 1 0" />
  <origin  xyz="0.0 0.0 0.041666666666666664" />
 </joint>
 <joint  type="revolute"  name="joint7" >
  <parent  link="link6" />
  <child  link="link7" />
  <dynamics  damping="0.0" />
  <limit  upper="2.5"  lower="-2.5"  effort="20"  velocity="20" />
  <axis  xyz="1 0 0" />
  <origin  xyz="0.0 0.0 0" />
 </joint>
 <joint  type="revolute"  name="joint8" >
  <parent  link="link7" />
  <child  link="link8" />
  <dynamics  damping="0.0" />
  <limit  upper="2.5"  lower="-2.5"  effort="20"  velocity="20" />
  <axis  xyz="0 1 0" />
  <origin  xyz="0.0 0.0 0.041666666666666664" />
 </joint>
 <joint  type="revolute"  name="joint9" >
  <parent  link="link8" />
  <child  link="link9" />
  <dynamics  damping="0.0" />
  <limit  upper="2.5"  lower="-2.5"  effort="20"  velocity="20" />
  <axis  xyz="1 0 0" />
  <origin  xyz="0.0 0.0 0" />
 </joint>
 <joint  type="revolute"  name="joint10" >
  <parent  link="link9" />
  <child  link="link10" />
  <dynamics  damping="0.0" />
  <limit  upper="2.5"  lower="-2.5"  effort="20"  velocity="20" />
  <axis  xyz="0 1 0" />
  <origin  xyz="0.0 0.0 0.041666666666666664" />
 </joint>
 <joint  type="revolute"  name="joint11" >
  <parent  link="link10" />
  <child  link="link11" />
  <dynamics  damping="0.0" />
  <limit  upper="2.5"  lower="-2.5"  effort="20"  velocity="20" />
  <axis  xyz="1 0 0" />
  <origin  xyz="0.0 0.0 0" />
 </joint>
 <joint  type="revolute"  name="joint12" >
  <parent  link="link11" />
  <child  link="link12" />
  <dynamics  damping="0.0" />
  <limit  upper="2.5"  lower="-2.5"  effort="20"  velocity="20" />
  <axis  xyz="0 1 0" />
  <origin  xyz="0.0 0.0 0.041666666666666664" />
 </joint>
 <joint  type="revolute"  name="joint13" >
  <parent  link="link12" />
  <child  link="link13" />
  <dynamics  damping="0.0" />
  <limit  upper="2.5"  lower="-2.5"  effort="20"  velocity="20" />
  <axis  xyz="1 0 0" />
  <origin  xyz="0.0 0.0 0" />
 </joint>
 <joint  type="revolute"  name="joint14" >
  <parent  link="link13" />
  <child  link="link14" />
  <dynamics  damping="0.0" />
  <limit  upper="2.5"  lower="-2.5"  effort="20"  velocity="20" />
  <axis  xyz="0 1 0" />
  <origin  xyz="0.0 0.0 0.041666666666666664" />
 </joint>
 <joint  type="revolute"  name="joint15" >
  <parent  link="link14" />
  <child  link="link15" />
  <dynamics  damping="0.0" />
  <limit  upper="2.5"  lower="-2.5"  effort="20"  velocity="20" />
  <axis  xyz="1 0 0" />
  <origin  xyz="0.0 0.0 0" />
 </joint>
 <joint  type="revolute"  name="joint16" >
  <parent  link="link15" />
  <child  link="link16" />
  <dynamics  damping="0.0" />
  <limit  upper="2.5"  lower="-2.5"  effort="20"  velocity="20" />
  <axis  xyz="0 1 0" />
  <origin  xyz="0.0 0.0 0.041666666666666664" />
 </joint>
 <joint  type="revolute"  name="joint17" >
  <parent  link="link16" />
  <child  link="link17" />
  <dynamics  damping="0.0" />
  <limit  upper="2.5"  lower="-2.5"  effort="20"  velocity="20" />
  <axis  xyz="1 0 0" />
  <origin  xyz="0.0 0.0 0" />
 </joint>
 <joint  type="revolute"  name="joint18" >
  <parent  link="link17" />
  <child  link="link18" />
  <dynamics  damping="0.0" />
  <limit  upper="2.5"  lower="-2.5"  effort="20"  velocity="20" />
  <axis  xyz="0 1 0" />
  <origin  xyz="0.0 0.0 0.041666666666666664" />
 </joint>
 <joint  type="revolute"  name="joint19" >
  <parent  link="link18" />
  <child  link="link19" />
  <dynamics  damping="0.0" />
  <limit  upper="2.5"  lower="-2.5"  effort="20"  velocity="20" />
  <axis  xyz="1 0 0" />
  <origin  xyz="0.0 0.0 0" />
 </joint>
 <joint  type="revolute"  name="joint20" >
  <parent  link="link19" />
  <child  link="link20" />
  <dynamics  damping="0.0" />
  <limit  upper="2.5"  lower="-2.5"  effort="20"  velocity="20" />
  <axis  xyz="0 1 0" />
  <origin  xyz="0.0 0.0 0.041666666666666664" />
 </joint>
 <joint  type="revolute"  name="joint21" >
  <parent  link="link20" />
  <child  link="link21" />
  <dynamics  damping="0.0" />
  <limit  upper="2.5"  lower="-2.5"  effort="20"  velocity="20" />
  <axis  xyz="1 0 0" />
  <origin  xyz="0.0 0.0 0" />
 </joint>
 <joint  type="revolute"  name="joint22" >
  <parent  link="link21" />
  <child  link="link22" />
  <dynamics  damping="0.0" />
  <limit  upper="2.5"  lower="-2.5"  effort="20"  velocity="20" />
  <axis  xyz="0 1 0" />
  <origin  xyz="0.0 0.0 0.041666666666666664" />
 </joint>
 <joint  type="revolute"  name="joint23" >
  <parent  link="link22" />
  <child  link="link23" />
  <dynamics  damping="0.0" />
  <limit  upper="2.5"  lower="-2.5"  effort="20"  velocity="20" />
  <axis  xyz="1 0 0" />
  <origin  xyz="0.0 0.0 0" />
 </joint>
 <joint  type="revolute"  name="joint24" >
  <parent  link="link23" />
  <child  link="link24" />
  <dynamics  damping="0.0" />
  <limit  upper="2.5"  lower="-2.5"  effort="20"  velocity="20" />
  <axis  xyz="0 1 0" />
  <origin  xyz="0.0 0.0 0.041666666666666664" />
 </joint>
 <joint  type="revolute"  name="joint25" >
  <parent  link="link24" />
  <child  link="link25" />
  <dynamics  damping="0.0" />
  <limit  upper="2.5"  lower="-2.5"  effort="20"  velocity="20" />
  <axis  xyz="1 0 0" />
  <origin  xyz="0.0 0.0 0" />
 </joint>
 <joint  type="revolute"  name="joint26" >
  <parent  link="link25" />
  <child  link="link26" />
  <dynamics  damping="0.0" />
  <limit  upper="2.5"  lower="-2.5"  effort="20"  velocity="20" />
  <axis  xyz="0 1 0" />
  <origin  xyz="0.0 0.0 0.041666666666666664" />
 </joint>
 <joint  type="revolute"  name="joint27" >
  <parent  link="link26" />
  <child  link="link27" />
  <dynamics  damping="0.0" />
  <limit  upper="2.5"  lower="-2.5"  effort="20"  velocity="20" />
  <axis  xyz="1 0 0" />
  <origin  xyz="0.0 0.0 0" />
 </joint>
 <joint  type="revolute"  name="joint28" >
  <parent  link="link27" />
  <child  link="link28" />
  <dynamics  damping="0.0" />
  <limit  upper="2.5"  lower="-2.5"  effort="20"  velocity="20" />
  <axis  xyz="0 1 0" />
  <origin  xyz="0.0 0.0 0.041666666666666664" />
 </joint>
 <joint  type="revolute"  name="joint29" >
  <parent  link="link28" />
  <child  link="link29" />
  <dynamics  damping="0.0" />
  <limit  upper="2.5"  lower="-2.5"  effort="20"  velocity="20" />
  <axis  xyz="1 0 0" />
  <origin  xyz="0.0 0.0 0" />
 </joint>
 <joint  type="revolute"  name="joint30" >
  <parent  link="link29" />
  <child  link="link30" />
  <dynamics  damping="0.0" />
  <limit  upper="2.5"  lower="-2.5"  effort="20"  velocity="20" />
  <axis  xyz="0 1 0" />
  <origin  xyz="0.0 0.0 0.041666666666666664" />
 </joint>
 <joint  type="revolute"  name="joint31" >
  <parent  link="link30" />
  <child  link="link31" />
  <dynamics  damping="0.0" />
  <limit  upper="2.5"  lower="-2.5"  effort="20"  velocity="20" />
  <axis  xyz="1 0 0" />
  <origin  xyz="0.0 0.0 0" />
 </joint>
 <joint  type="revolute"  name="joint32" >
  <parent  link="link31" />
  <child  link="link32" />
  <dynamics  damping="0.0" />
  <limit  upper="2.5"  lower="-2.5"  effort="20"  velocity="20" />
  <axis  xyz="0 1 0" />
  <origin  xyz="0.0 0.0 0.041666666666666664" />
 </joint>
 <joint  type="revolute"  name="joint33" >
  <parent  link="link32" />
  <child  link="link33" />
  <dynamics  damping="0.0" />
  <limit  upper="2.5"  lower="-2.5"  effort="20"  velocity="20" />
  <axis  xyz="1 0 0" />
  <origin  xyz="0.0 0.0 0" />
 </joint>
 <joint  type="revolute"  name="joint34" >
  <parent  link="link33" />
  <child  link="link34" />
  <dynamics  damping="0.0" />
  <limit  upper="2.5"  lower="-2.5"  effort="20"  velocity="20" />
  <axis  xyz="0 1 0" />
  <origin  xyz="0.0 0.0 0.041666666666666664" />
 </joint>
 <joint  type="revolute"  name="joint35" >
  <parent  link="link34" />
  <child  link="link35" />
  <dynamics  damping="0.0" />
  <limit  upper="2.5"  lower="-2.5"  effort="20"  velocity="20" />
  <axis  xyz="1 0 0" />
  <origin  xyz="0.0 0.0 0" />
 </joint>
 <joint  type="revolute"  name="joint36" >
  <parent  link="link35" />
  <child  link="link36" />
  <dynamics  damping="0.0" />
  <limit  upper="2.5"  lower="-2.5"  effort="20"  velocity="20" />
  <axis  xyz="0 1 0" />
  <origin  xyz="0.0 0.0 0.041666666666666664" />
 </joint>
 <joint  type="revolute"  name="joint37" >
  <parent  link="link36" />
  <child  link="link37" />
  <dynamics  damping="0.0" />
  <limit  upper="2.5"  lower="-2.5"  effort="20"  velocity="20" />
  <axis  xyz="1 0 0" />
  <origin  xyz="0.0 0.0 0" />
 </joint>
 <joint  type="revolute"  name="joint38" >
  <parent  link="link37" />
  <child  link="link38" />
  <dynamics  damping="0.0" />
  <limit  upper="2.5"  lower="-2.5"  effort="20"  velocity="20" />
  <axis  xyz="0 1 0" />
  <origin  xyz="0.0 0.0 0.041666666666666664" />
 </joint>
 <joint  type="revolute"  name="joint39" >
  <parent  link="link38" />
  <child  link="link39" />
  <dynamics  damping="0.0" />
  <limit  upper="2.5"  lower="-2.5"  effort="20"  velocity="20" />
  <axis  xyz="1 0 0" />
  <origin  xyz="0.0 0.0 0" />
 </joint>
 <joint  type="revolute"  name="joint40" >
  <parent  link="link39" />
  <child  link="link40" />
  <dynamics  damping="0.0" />
  <limit  upper="2.5"  lower="-2.5"  effort="20"  velocity="20" />
  <axis  xyz="0 1 0" />
  <origin  xyz="0.0 0.0 0.041666666666666664" />
 </joint>
 <joint  type="revolute"  name="joint41" >
  <parent  link="link40" />
  <child  link="link41" />
  <dynamics  damping="0.0" />
  <limit  upper="2.5"  lower="-2.5"  effort="20"  velocity="20" />
  <axis  xyz="1 0 0" />
  <origin  xyz="0.0 0.0 0" />
 </joint>
 <joint  type="revolute"  name="joint42" >
  <parent  link="link41" />
  <child  link="link42" />
  <dynamics  damping="0.0" />
  <limit  upper="2.5"  lower="-2.5"  effort="20"  velocity="20" />
  <axis  xyz="0 1 0" />
  <origin  xyz="0.0 0.0 0.041666666666666664" />
 </joint>
 <joint  type="revolute"  name="joint43" >
  <parent  link="link42" />
  <child  link="link43" />
  <dynamics  damping="0.0" />
  <limit  upper="2.5"  lower="-2.5"  effort="20"  velocity="20" />
  <axis  xyz="1 0 0" />
  <origin  xyz="0.0 0.0 0" />
 </joint>
 <joint  type="revolute"  name="joint44" >
  <parent  link="link43" />
  <child  link="link44" />
  <dynamics  damping="0.0" />
  <limit  upper="2.5"  lower="-2.5"  effort="20"  velocity="20" />
  <axis  xyz="0 1 0" />
  <origin  xyz="0.0 0.0 0.041666666666666664" />
 </joint>
 <joint  type="revolute"  name="joint45" >
  <parent  link="link44" />
  <child  link="link45" />
  <dynamics  damping="0.0" />
  <limit  upper="2.5"  lower="-2.5"  effort="20"  velocity="20" />
  <axis  xyz="1 0 0" />
  <origin  xyz="0.0 0.0 0" />
 </joint>
 <joint  type="revolute"  name="joint46" >
  <parent  link="link45" />
  <child  link="link46" />
  <dynamics  damping="0.0" />
  <limit  upper="2.5"  lower="-2.5"  effort="20"  velocity="20" />
  <axis  xyz="0 1 0" />
  <origin  xyz="0.0 0.0 0.041666666666666664" />
 </joint>
 <joint  type="revolute"  name="joint47" >
  <parent  link="link46" />
  <child  link="link47" />
  <dynamics  damping="0.0" />
  <limit  upper="2.5"  lower="-2.5"  effort="20"  velocity="20" />
  <axis  xyz="1 0 0" />
  <origin  xyz="0.0 0.0 0" />
 </joint>
</robot>
