<?xml version="1.0" ?>
<robot name="panda" xmlns:xacro="http://www.ros.org/wiki/xacro">
  <link name="panda_link0">
    <visual>
      <geometry>
        <mesh filename="package://franka_description/meshes/visual/link0.dae"/>
      </geometry>
    </visual>
    <collision>
      <geometry>
        <mesh filename="package://franka_description/meshes/collision/link0.obj"/>
      </geometry>
    </collision>
  </link>
  <link name="panda_link1">
    <visual>
      <geometry>
        <mesh filename="package://franka_description/meshes/visual/link1.dae"/>
      </geometry>
    </visual>
    <collision>
      <geometry>
        <mesh filename="package://franka_description/meshes/collision/link1.obj"/>
      </geometry>
    </collision>
  </link>
  <joint name="panda_joint1" type="revolute">
    <safety_controller k_position="100.0" k_velocity="40.0" soft_lower_limit="-2.8973" soft_upper_limit="2.8973"/>
    <origin rpy="0 0 0" xyz="0 0 0.333"/>
    <parent link="panda_link0"/>
    <child link="panda_link1"/>
    <axis xyz="0 0 1"/>
    <dynamics damping="10.0"/>
    <limit effort="87" lower="-2.8973" upper="2.8973" velocity="2.1750"/>
  </joint>
  <link name="panda_link2">
    <visual>
      <geometry>
        <mesh filename="package://franka_description/meshes/visual/link2.dae"/>
      </geometry>
    </visual>
    <collision>
      <geometry>
        <mesh filename="package://franka_description/meshes/collision/link2.obj"/>
      </geometry>
    </collision>
  </link>
  <joint name="panda_joint2" type="revolute">
    <safety_controller k_position="100.0" k_velocity="40.0" soft_lower_limit="-1.7628" soft_upper_limit="1.7628"/>
    <origin rpy="-1.57079632679 0 0" xyz="0 0 0"/>
    <parent link="panda_link1"/>
    <child link="panda_link2"/>
    <axis xyz="0 0 1"/>
    <dynamics damping="10.0"/>
    <limit effort="87" lower="-1.7628" upper="1.7628" velocity="2.1750"/>
  </joint>
  <link name="panda_link3">
    <visual>
      <geometry>
        <mesh filename="package://franka_description/meshes/visual/link3.dae"/>
      </geometry>
    </visual>
    <collision>
      <geometry>
        <mesh filename="package://franka_description/meshes/collision/link3.obj"/>
      </geometry>
    </collision>
  </link>
  <joint name="panda_joint3" type="revolute">
    <safety_controller k_position="100.0" k_velocity="40.0" soft_lower_limit="-2.8973" soft_upper_limit="2.8973"/>
    <origin rpy="1.57079632679 0 0" xyz="0 -0.316 0"/>
    <parent link="panda_link2"/>
    <child link="panda_link3"/>
    <axis xyz="0 0 1"/>
    <dynamics damping="10.0"/>
    <limit effort="87" lower="-2.8973" upper="2.8973" velocity="2.1750"/>
  </joint>
  <link name="panda_link4">
    <visual>
      <geometry>
        <mesh filename="package://franka_description/meshes/visual/link4.dae"/>
      </geometry>
    </visual>
    <collision>
      <geometry>
        <mesh filename="package://franka_description/meshes/collision/link4.obj"/>
      </geometry>
    </collision>
  </link>
  <joint name="panda_joint4" type="revolute">
    <safety_controller k_position="100.0" k_velocity="40.0" soft_lower_limit="-3.0718" soft_upper_limit="-0.0698"/>
    <origin rpy="1.57079632679 0 0" xyz="0.0825 0 0"/>
    <parent link="panda_link3"/>
    <child link="panda_link4"/>
    <axis xyz="0 0 1"/>
    <dynamics damping="10.0"/>
    <limit effort="87" lower="-3.0718" upper="-0.0698" velocity="2.1750"/>
    <!-- something is weird with this joint limit config
    <dynamics damping="10.0"/>
    <limit effort="87" lower="-3.0" upper="0.087" velocity="2.1750"/>  -->
  </joint>
  <link name="panda_link5">
    <visual>
      <geometry>
        <mesh filename="package://franka_description/meshes/visual/link5.dae"/>
      </geometry>
    </visual>
    <collision>
      <geometry>
        <mesh filename="package://franka_description/meshes/collision/link5.obj"/>
      </geometry>
    </collision>
  </link>
  <joint name="panda_joint5" type="revolute">
    <safety_controller k_position="100.0" k_velocity="40.0" soft_lower_limit="-2.8973" soft_upper_limit="2.8973"/>
    <origin rpy="-1.57079632679 0 0" xyz="-0.0825 0.384 0"/>
    <parent link="panda_link4"/>
    <child link="panda_link5"/>
    <axis xyz="0 0 1"/>
    <dynamics damping="10.0"/>
    <limit effort="12" lower="-2.8973" upper="2.8973" velocity="2.6100"/>
  </joint>
  <link name="panda_link6">
    <visual>
      <geometry>
        <mesh filename="package://franka_description/meshes/visual/link6.dae"/>
      </geometry>
    </visual>
    <collision>
      <geometry>
        <mesh filename="package://franka_description/meshes/collision/link6.obj"/>
      </geometry>
    </collision>
  </link>
  <joint name="panda_joint6" type="revolute">
    <safety_controller k_position="100.0" k_velocity="40.0" soft_lower_limit="-0.0175" soft_upper_limit="3.7525"/>
    <origin rpy="1.57079632679 0 0" xyz="0 0 0"/>
    <parent link="panda_link5"/>
    <child link="panda_link6"/>
    <axis xyz="0 0 1"/>
    <dynamics damping="10.0"/>
    <limit effort="12" lower="-0.0175" upper="3.7525" velocity="2.6100"/>
    <!-- <dynamics damping="10.0"/>
    <limit effort="12" lower="-0.0873" upper="3.0" velocity="2.6100"/> -->
  </joint>
  <link name="panda_link7">
    <visual>
      <geometry>
        <mesh filename="package://franka_description/meshes/visual/link7.dae"/>
      </geometry>
    </visual>
    <collision>
      <geometry>
        <mesh filename="package://franka_description/meshes/collision/link7.obj"/>
      </geometry>
    </collision>
  </link>
  <joint name="panda_joint7" type="revolute">
    <safety_controller k_position="100.0" k_velocity="40.0" soft_lower_limit="-2.8973" soft_upper_limit="2.8973"/>
    <origin rpy="1.57079632679 0 0" xyz="0.088 0 0"/>
    <parent link="panda_link6"/>
    <child link="panda_link7"/>
    <axis xyz="0 0 1"/>
    <dynamics damping="10.0"/>
    <limit effort="12" lower="-2.8973" upper="2.8973" velocity="2.6100"/>
  </joint>
  <!--
  <link name="panda_link8"/>
  <joint name="panda_joint8" type="fixed">
    <origin rpy="0 0 0" xyz="0 0 0.107"/>
    <parent link="panda_link7"/>
    <child link="panda_link8"/>
    <axis xyz="0 0 0"/>
  </joint>
  Removing this joint seems to help with some stability things
  -->
  <joint name="panda_hand_joint" type="fixed">
    <!--
    <parent link="panda_link8"/>
    -->
    <parent link="panda_link7"/>
    <child link="panda_hand"/>
    <origin rpy="0 0 -0.785398163397" xyz="0 0 0.107"/>
    <!--
    <origin rpy="0 0 -0.785398163397" xyz="0 0 0"/>
    -->
  </joint>
  <link name="panda_hand">
    <visual>
      <geometry>
        <mesh filename="package://franka_description/meshes/visual/hand.dae"/>
      </geometry>
    </visual>
    <collision>
      <geometry>
        <mesh filename="package://franka_description/meshes/collision/hand.obj"/>
      </geometry>
    </collision>
  </link>
 <link  name="link0" >
  <inertial >
   <mass  value="0.012499999999999999" />
   <origin  xyz="0.0 0.0 0.0" />
  </inertial>
  <visual >
   <geometry >
    <cylinder  length="0"  radius="0" />
   </geometry>
   <origin  xyz="0.0 0.0 0.0" />
  </visual>
  <collision >
   <geometry >
    <cylinder  length="0"  radius="0" />
   </geometry>
   <origin  xyz="0.0 0.0 0.0" />
  </collision>
 </link>
 <link  name="link1" >
  <inertial >
   <mass  value="0.012499999999999999" />
   <origin  xyz="0.0 0.0 0.020833333333333332" />
  </inertial>
  <visual >
   <geometry >
    <cylinder  length="0.041666666666666664"  radius="0.02" />
   </geometry>
   <origin  xyz="0.0 0.0 0.020833333333333332" />
  </visual>
  <collision >
   <geometry >
    <cylinder  length="0.041666666666666664"  radius="0.02" />
   </geometry>
   <origin  xyz="0.0 0.0 0.020833333333333332" />
  </collision>
 </link>
 <link  name="link2" >
  <inertial >
   <mass  value="0.012499999999999999" />
   <origin  xyz="0.0 0.0 0.0" />
  </inertial>
  <visual >
   <geometry >
    <cylinder  length="0"  radius="0" />
   </geometry>
   <origin  xyz="0.0 0.0 0.0" />
  </visual>
  <collision >
   <geometry >
    <cylinder  length="0"  radius="0" />
   </geometry>
   <origin  xyz="0.0 0.0 0.0" />
  </collision>
 </link>
 <link  name="link3" >
  <inertial >
   <mass  value="0.012499999999999999" />
   <origin  xyz="0.0 0.0 0.020833333333333332" />
  </inertial>
  <visual >
   <geometry >
    <cylinder  length="0.041666666666666664"  radius="0.02" />
   </geometry>
   <origin  xyz="0.0 0.0 0.020833333333333332" />
  </visual>
  <collision >
   <geometry >
    <cylinder  length="0.041666666666666664"  radius="0.02" />
   </geometry>
   <origin  xyz="0.0 0.0 0.020833333333333332" />
  </collision>
 </link>
 <link  name="link4" >
  <inertial >
   <mass  value="0.012499999999999999" />
   <origin  xyz="0.0 0.0 0.0" />
  </inertial>
  <visual >
   <geometry >
    <cylinder  length="0"  radius="0" />
   </geometry>
   <origin  xyz="0.0 0.0 0.0" />
  </visual>
  <collision >
   <geometry >
    <cylinder  length="0"  radius="0" />
   </geometry>
   <origin  xyz="0.0 0.0 0.0" />
  </collision>
 </link>
 <link  name="link5" >
  <inertial >
   <mass  value="0.012499999999999999" />
   <origin  xyz="0.0 0.0 0.020833333333333332" />
  </inertial>
  <visual >
   <geometry >
    <cylinder  length="0.041666666666666664"  radius="0.02" />
   </geometry>
   <origin  xyz="0.0 0.0 0.020833333333333332" />
  </visual>
  <collision >
   <geometry >
    <cylinder  length="0.041666666666666664"  radius="0.02" />
   </geometry>
   <origin  xyz="0.0 0.0 0.020833333333333332" />
  </collision>
 </link>
 <link  name="link6" >
  <inertial >
   <mass  value="0.012499999999999999" />
   <origin  xyz="0.0 0.0 0.0" />
  </inertial>
  <visual >
   <geometry >
    <cylinder  length="0"  radius="0" />
   </geometry>
   <origin  xyz="0.0 0.0 0.0" />
  </visual>
  <collision >
   <geometry >
    <cylinder  length="0"  radius="0" />
   </geometry>
   <origin  xyz="0.0 0.0 0.0" />
  </collision>
 </link>
 <link  name="link7" >
  <inertial >
   <mass  value="0.012499999999999999" />
   <origin  xyz="0.0 0.0 0.020833333333333332" />
  </inertial>
  <visual >
   <geometry >
    <cylinder  length="0.041666666666666664"  radius="0.02" />
   </geometry>
   <origin  xyz="0.0 0.0 0.020833333333333332" />
  </visual>
  <collision >
   <geometry >
    <cylinder  length="0.041666666666666664"  radius="0.02" />
   </geometry>
   <origin  xyz="0.0 0.0 0.020833333333333332" />
  </collision>
 </link>
 <link  name="link8" >
  <inertial >
   <mass  value="0.012499999999999999" />
   <origin  xyz="0.0 0.0 0.0" />
  </inertial>
  <visual >
   <geometry >
    <cylinder  length="0"  radius="0" />
   </geometry>
   <origin  xyz="0.0 0.0 0.0" />
  </visual>
  <collision >
   <geometry >
    <cylinder  length="0"  radius="0" />
   </geometry>
   <origin  xyz="0.0 0.0 0.0" />
  </collision>
 </link>
 <link  name="link9" >
  <inertial >
   <mass  value="0.012499999999999999" />
   <origin  xyz="0.0 0.0 0.020833333333333332" />
  </inertial>
  <visual >
   <geometry >
    <cylinder  length="0.041666666666666664"  radius="0.02" />
   </geometry>
   <origin  xyz="0.0 0.0 0.020833333333333332" />
  </visual>
  <collision >
   <geometry >
    <cylinder  length="0.041666666666666664"  radius="0.02" />
   </geometry>
   <origin  xyz="0.0 0.0 0.020833333333333332" />
  </collision>
 </link>
 <link  name="link10" >
  <inertial >
   <mass  value="0.012499999999999999" />
   <origin  xyz="0.0 0.0 0.0" />
  </inertial>
  <visual >
   <geometry >
    <cylinder  length="0"  radius="0" />
   </geometry>
   <origin  xyz="0.0 0.0 0.0" />
  </visual>
  <collision >
   <geometry >
    <cylinder  length="0"  radius="0" />
   </geometry>
   <origin  xyz="0.0 0.0 0.0" />
  </collision>
 </link>
 <link  name="link11" >
  <inertial >
   <mass  value="0.012499999999999999" />
   <origin  xyz="0.0 0.0 0.020833333333333332" />
  </inertial>
  <visual >
   <geometry >
    <cylinder  length="0.041666666666666664"  radius="0.02" />
   </geometry>
   <origin  xyz="0.0 0.0 0.020833333333333332" />
  </visual>
  <collision >
   <geometry >
    <cylinder  length="0.041666666666666664"  radius="0.02" />
   </geometry>
   <origin  xyz="0.0 0.0 0.020833333333333332" />
  </collision>
 </link>
 <link  name="link12" >
  <inertial >
   <mass  value="0.012499999999999999" />
   <origin  xyz="0.0 0.0 0.0" />
  </inertial>
  <visual >
   <geometry >
    <cylinder  length="0"  radius="0" />
   </geometry>
   <origin  xyz="0.0 0.0 0.0" />
  </visual>
  <collision >
   <geometry >
    <cylinder  length="0"  radius="0" />
   </geometry>
   <origin  xyz="0.0 0.0 0.0" />
  </collision>
 </link>
 <link  name="link13" >
  <inertial >
   <mass  value="0.012499999999999999" />
   <origin  xyz="0.0 0.0 0.020833333333333332" />
  </inertial>
  <visual >
   <geometry >
    <cylinder  length="0.041666666666666664"  radius="0.02" />
   </geometry>
   <origin  xyz="0.0 0.0 0.020833333333333332" />
  </visual>
  <collision >
   <geometry >
    <cylinder  length="0.041666666666666664"  radius="0.02" />
   </geometry>
   <origin  xyz="0.0 0.0 0.020833333333333332" />
  </collision>
 </link>
 <link  name="link14" >
  <inertial >
   <mass  value="0.012499999999999999" />
   <origin  xyz="0.0 0.0 0.0" />
  </inertial>
  <visual >
   <geometry >
    <cylinder  length="0"  radius="0" />
   </geometry>
   <origin  xyz="0.0 0.0 0.0" />
  </visual>
  <collision >
   <geometry >
    <cylinder  length="0"  radius="0" />
   </geometry>
   <origin  xyz="0.0 0.0 0.0" />
  </collision>
 </link>
 <link  name="link15" >
  <inertial >
   <mass  value="0.012499999999999999" />
   <origin  xyz="0.0 0.0 0.020833333333333332" />
  </inertial>
  <visual >
   <geometry >
    <cylinder  length="0.041666666666666664"  radius="0.02" />
   </geometry>
   <origin  xyz="0.0 0.0 0.020833333333333332" />
  </visual>
  <collision >
   <geometry >
    <cylinder  length="0.041666666666666664"  radius="0.02" />
   </geometry>
   <origin  xyz="0.0 0.0 0.020833333333333332" />
  </collision>
 </link>
 <link  name="link16" >
  <inertial >
   <mass  value="0.012499999999999999" />
   <origin  xyz="0.0 0.0 0.0" />
  </inertial>
  <visual >
   <geometry >
    <cylinder  length="0"  radius="0" />
   </geometry>
   <origin  xyz="0.0 0.0 0.0" />
  </visual>
  <collision >
   <geometry >
    <cylinder  length="0"  radius="0" />
   </geometry>
   <origin  xyz="0.0 0.0 0.0" />
  </collision>
 </link>
 <link  name="link17" >
  <inertial >
   <mass  value="0.012499999999999999" />
   <origin  xyz="0.0 0.0 0.020833333333333332" />
  </inertial>
  <visual >
   <geometry >
    <cylinder  length="0.041666666666666664"  radius="0.02" />
   </geometry>
   <origin  xyz="0.0 0.0 0.020833333333333332" />
  </visual>
  <collision >
   <geometry >
    <cylinder  length="0.041666666666666664"  radius="0.02" />
   </geometry>
   <origin  xyz="0.0 0.0 0.020833333333333332" />
  </collision>
 </link>
 <link  name="link18" >
  <inertial >
   <mass  value="0.012499999999999999" />
   <origin  xyz="0.0 0.0 0.0" />
  </inertial>
  <visual >
   <geometry >
    <cylinder  length="0"  radius="0" />
   </geometry>
   <origin  xyz="0.0 0.0 0.0" />
  </visual>
  <collision >
   <geometry >
    <cylinder  length="0"  radius="0" />
   </geometry>
   <origin  xyz="0.0 0.0 0.0" />
  </collision>
 </link>
 <link  name="link19" >
  <inertial >
   <mass  value="0.012499999999999999" />
   <origin  xyz="0.0 0.0 0.020833333333333332" />
  </inertial>
  <visual >
   <geometry >
    <cylinder  length="0.041666666666666664"  radius="0.02" />
   </geometry>
   <origin  xyz="0.0 0.0 0.020833333333333332" />
  </visual>
  <collision >
   <geometry >
    <cylinder  length="0.041666666666666664"  radius="0.02" />
   </geometry>
   <origin  xyz="0.0 0.0 0.020833333333333332" />
  </collision>
 </link>
 <link  name="link20" >
  <inertial >
   <mass  value="0.012499999999999999" />
   <origin  xyz="0.0 0.0 0.0" />
  </inertial>
  <visual >
   <geometry >
    <cylinder  length="0"  radius="0" />
   </geometry>
   <origin  xyz="0.0 0.0 0.0" />
  </visual>
  <collision >
   <geometry >
    <cylinder  length="0"  radius="0" />
   </geometry>
   <origin  xyz="0.0 0.0 0.0" />
  </collision>
 </link>
 <link  name="link21" >
  <inertial >
   <mass  value="0.012499999999999999" />
   <origin  xyz="0.0 0.0 0.020833333333333332" />
  </inertial>
  <visual >
   <geometry >
    <cylinder  length="0.041666666666666664"  radius="0.02" />
   </geometry>
   <origin  xyz="0.0 0.0 0.020833333333333332" />
  </visual>
  <collision >
   <geometry >
    <cylinder  length="0.041666666666666664"  radius="0.02" />
   </geometry>
   <origin  xyz="0.0 0.0 0.020833333333333332" />
  </collision>
 </link>
 <link  name="link22" >
  <inertial >
   <mass  value="0.012499999999999999" />
   <origin  xyz="0.0 0.0 0.0" />
  </inertial>
  <visual >
   <geometry >
    <cylinder  length="0"  radius="0" />
   </geometry>
   <origin  xyz="0.0 0.0 0.0" />
  </visual>
  <collision >
   <geometry >
    <cylinder  length="0"  radius="0" />
   </geometry>
   <origin  xyz="0.0 0.0 0.0" />
  </collision>
 </link>
 <link  name="link23" >
  <inertial >
   <mass  value="0.012499999999999999" />
   <origin  xyz="0.0 0.0 0.020833333333333332" />
  </inertial>
  <visual >
   <geometry >
    <cylinder  length="0.041666666666666664"  radius="0.02" />
   </geometry>
   <origin  xyz="0.0 0.0 0.020833333333333332" />
  </visual>
  <collision >
   <geometry >
    <cylinder  length="0.041666666666666664"  radius="0.02" />
   </geometry>
   <origin  xyz="0.0 0.0 0.020833333333333332" />
  </collision>
 </link>
 <link  name="link24" >
  <inertial >
   <mass  value="0.012499999999999999" />
   <origin  xyz="0.0 0.0 0.0" />
  </inertial>
  <visual >
   <geometry >
    <cylinder  length="0"  radius="0" />
   </geometry>
   <origin  xyz="0.0 0.0 0.0" />
  </visual>
  <collision >
   <geometry >
    <cylinder  length="0"  radius="0" />
   </geometry>
   <origin  xyz="0.0 0.0 0.0" />
  </collision>
 </link>
 <link  name="link25" >
  <inertial >
   <mass  value="0.012499999999999999" />
   <origin  xyz="0.0 0.0 0.020833333333333332" />
  </inertial>
  <visual >
   <geometry >
    <cylinder  length="0.041666666666666664"  radius="0.02" />
   </geometry>
   <origin  xyz="0.0 0.0 0.020833333333333332" />
  </visual>
  <collision >
   <geometry >
    <cylinder  length="0.041666666666666664"  radius="0.02" />
   </geometry>
   <origin  xyz="0.0 0.0 0.020833333333333332" />
  </collision>
 </link>
 <link  name="link26" >
  <inertial >
   <mass  value="0.012499999999999999" />
   <origin  xyz="0.0 0.0 0.0" />
  </inertial>
  <visual >
   <geometry >
    <cylinder  length="0"  radius="0" />
   </geometry>
   <origin  xyz="0.0 0.0 0.0" />
  </visual>
  <collision >
   <geometry >
    <cylinder  length="0"  radius="0" />
   </geometry>
   <origin  xyz="0.0 0.0 0.0" />
  </collision>
 </link>
 <link  name="link27" >
  <inertial >
   <mass  value="0.012499999999999999" />
   <origin  xyz="0.0 0.0 0.020833333333333332" />
  </inertial>
  <visual >
   <geometry >
    <cylinder  length="0.041666666666666664"  radius="0.02" />
   </geometry>
   <origin  xyz="0.0 0.0 0.020833333333333332" />
  </visual>
  <collision >
   <geometry >
    <cylinder  length="0.041666666666666664"  radius="0.02" />
   </geometry>
   <origin  xyz="0.0 0.0 0.020833333333333332" />
  </collision>
 </link>
 <link  name="link28" >
  <inertial >
   <mass  value="0.012499999999999999" />
   <origin  xyz="0.0 0.0 0.0" />
  </inertial>
  <visual >
   <geometry >
    <cylinder  length="0"  radius="0" />
   </geometry>
   <origin  xyz="0.0 0.0 0.0" />
  </visual>
  <collision >
   <geometry >
    <cylinder  length="0"  radius="0" />
   </geometry>
   <origin  xyz="0.0 0.0 0.0" />
  </collision>
 </link>
 <link  name="link29" >
  <inertial >
   <mass  value="0.012499999999999999" />
   <origin  xyz="0.0 0.0 0.020833333333333332" />
  </inertial>
  <visual >
   <geometry >
    <cylinder  length="0.041666666666666664"  radius="0.02" />
   </geometry>
   <origin  xyz="0.0 0.0 0.020833333333333332" />
  </visual>
  <collision >
   <geometry >
    <cylinder  length="0.041666666666666664"  radius="0.02" />
   </geometry>
   <origin  xyz="0.0 0.0 0.020833333333333332" />
  </collision>
 </link>
 <link  name="link30" >
  <inertial >
   <mass  value="0.012499999999999999" />
   <origin  xyz="0.0 0.0 0.0" />
  </inertial>
  <visual >
   <geometry >
    <cylinder  length="0"  radius="0" />
   </geometry>
   <origin  xyz="0.0 0.0 0.0" />
  </visual>
  <collision >
   <geometry >
    <cylinder  length="0"  radius="0" />
   </geometry>
   <origin  xyz="0.0 0.0 0.0" />
  </collision>
 </link>
 <link  name="link31" >
  <inertial >
   <mass  value="0.012499999999999999" />
   <origin  xyz="0.0 0.0 0.020833333333333332" />
  </inertial>
  <visual >
   <geometry >
    <cylinder  length="0.041666666666666664"  radius="0.02" />
   </geometry>
   <origin  xyz="0.0 0.0 0.020833333333333332" />
  </visual>
  <collision >
   <geometry >
    <cylinder  length="0.041666666666666664"  radius="0.02" />
   </geometry>
   <origin  xyz="0.0 0.0 0.020833333333333332" />
  </collision>
 </link>
 <link  name="link32" >
  <inertial >
   <mass  value="0.012499999999999999" />
   <origin  xyz="0.0 0.0 0.0" />
  </inertial>
  <visual >
   <geometry >
    <cylinder  length="0"  radius="0" />
   </geometry>
   <origin  xyz="0.0 0.0 0.0" />
  </visual>
  <collision >
   <geometry >
    <cylinder  length="0"  radius="0" />
   </geometry>
   <origin  xyz="0.0 0.0 0.0" />
  </collision>
 </link>
 <link  name="link33" >
  <inertial >
   <mass  value="0.012499999999999999" />
   <origin  xyz="0.0 0.0 0.020833333333333332" />
  </inertial>
  <visual >
   <geometry >
    <cylinder  length="0.041666666666666664"  radius="0.02" />
   </geometry>
   <origin  xyz="0.0 0.0 0.020833333333333332" />
  </visual>
  <collision >
   <geometry >
    <cylinder  length="0.041666666666666664"  radius="0.02" />
   </geometry>
   <origin  xyz="0.0 0.0 0.020833333333333332" />
  </collision>
 </link>
 <link  name="link34" >
  <inertial >
   <mass  value="0.012499999999999999" />
   <origin  xyz="0.0 0.0 0.0" />
  </inertial>
  <visual >
   <geometry >
    <cylinder  length="0"  radius="0" />
   </geometry>
   <origin  xyz="0.0 0.0 0.0" />
  </visual>
  <collision >
   <geometry >
    <cylinder  length="0"  radius="0" />
   </geometry>
   <origin  xyz="0.0 0.0 0.0" />
  </collision>
 </link>
 <link  name="link35" >
  <inertial >
   <mass  value="0.012499999999999999" />
   <origin  xyz="0.0 0.0 0.020833333333333332" />
  </inertial>
  <visual >
   <geometry >
    <cylinder  length="0.041666666666666664"  radius="0.02" />
   </geometry>
   <origin  xyz="0.0 0.0 0.020833333333333332" />
  </visual>
  <collision >
   <geometry >
    <cylinder  length="0.041666666666666664"  radius="0.02" />
   </geometry>
   <origin  xyz="0.0 0.0 0.020833333333333332" />
  </collision>
 </link>
 <link  name="link36" >
  <inertial >
   <mass  value="0.012499999999999999" />
   <origin  xyz="0.0 0.0 0.0" />
  </inertial>
  <visual >
   <geometry >
    <cylinder  length="0"  radius="0" />
   </geometry>
   <origin  xyz="0.0 0.0 0.0" />
  </visual>
  <collision >
   <geometry >
    <cylinder  length="0"  radius="0" />
   </geometry>
   <origin  xyz="0.0 0.0 0.0" />
  </collision>
 </link>
 <link  name="link37" >
  <inertial >
   <mass  value="0.012499999999999999" />
   <origin  xyz="0.0 0.0 0.020833333333333332" />
  </inertial>
  <visual >
   <geometry >
    <cylinder  length="0.041666666666666664"  radius="0.02" />
   </geometry>
   <origin  xyz="0.0 0.0 0.020833333333333332" />
  </visual>
  <collision >
   <geometry >
    <cylinder  length="0.041666666666666664"  radius="0.02" />
   </geometry>
   <origin  xyz="0.0 0.0 0.020833333333333332" />
  </collision>
 </link>
 <link  name="link38" >
  <inertial >
   <mass  value="0.012499999999999999" />
   <origin  xyz="0.0 0.0 0.0" />
  </inertial>
  <visual >
   <geometry >
    <cylinder  length="0"  radius="0" />
   </geometry>
   <origin  xyz="0.0 0.0 0.0" />
  </visual>
  <collision >
   <geometry >
    <cylinder  length="0"  radius="0" />
   </geometry>
   <origin  xyz="0.0 0.0 0.0" />
  </collision>
 </link>
 <link  name="link39" >
  <inertial >
   <mass  value="0.012499999999999999" />
   <origin  xyz="0.0 0.0 0.020833333333333332" />
  </inertial>
  <visual >
   <geometry >
    <cylinder  length="0.041666666666666664"  radius="0.02" />
   </geometry>
   <origin  xyz="0.0 0.0 0.020833333333333332" />
  </visual>
  <collision >
   <geometry >
    <cylinder  length="0.041666666666666664"  radius="0.02" />
   </geometry>
   <origin  xyz="0.0 0.0 0.020833333333333332" />
  </collision>
 </link>
 <link  name="link40" >
  <inertial >
   <mass  value="0.012499999999999999" />
   <origin  xyz="0.0 0.0 0.0" />
  </inertial>
  <visual >
   <geometry >
    <cylinder  length="0"  radius="0" />
   </geometry>
   <origin  xyz="0.0 0.0 0.0" />
  </visual>
  <collision >
   <geometry >
    <cylinder  length="0"  radius="0" />
   </geometry>
   <origin  xyz="0.0 0.0 0.0" />
  </collision>
 </link>
 <link  name="link41" >
  <inertial >
   <mass  value="0.012499999999999999" />
   <origin  xyz="0.0 0.0 0.020833333333333332" />
  </inertial>
  <visual >
   <geometry >
    <cylinder  length="0.041666666666666664"  radius="0.02" />
   </geometry>
   <origin  xyz="0.0 0.0 0.020833333333333332" />
  </visual>
  <collision >
   <geometry >
    <cylinder  length="0.041666666666666664"  radius="0.02" />
   </geometry>
   <origin  xyz="0.0 0.0 0.020833333333333332" />
  </collision>
 </link>
 <link  name="link42" >
  <inertial >
   <mass  value="0.012499999999999999" />
   <origin  xyz="0.0 0.0 0.0" />
  </inertial>
  <visual >
   <geometry >
    <cylinder  length="0"  radius="0" />
   </geometry>
   <origin  xyz="0.0 0.0 0.0" />
  </visual>
  <collision >
   <geometry >
    <cylinder  length="0"  radius="0" />
   </geometry>
   <origin  xyz="0.0 0.0 0.0" />
  </collision>
 </link>
 <link  name="link43" >
  <inertial >
   <mass  value="0.012499999999999999" />
   <origin  xyz="0.0 0.0 0.020833333333333332" />
  </inertial>
  <visual >
   <geometry >
    <cylinder  length="0.041666666666666664"  radius="0.02" />
   </geometry>
   <origin  xyz="0.0 0.0 0.020833333333333332" />
  </visual>
  <collision >
   <geometry >
    <cylinder  length="0.041666666666666664"  radius="0.02" />
   </geometry>
   <origin  xyz="0.0 0.0 0.020833333333333332" />
  </collision>
 </link>
 <link  name="link44" >
  <inertial >
   <mass  value="0.012499999999999999" />
   <origin  xyz="0.0 0.0 0.0" />
  </inertial>
  <visual >
   <geometry >
    <cylinder  length="0"  radius="0" />
   </geometry>
   <origin  xyz="0.0 0.0 0.0" />
  </visual>
  <collision >
   <geometry >
    <cylinder  length="0"  radius="0" />
   </geometry>
   <origin  xyz="0.0 0.0 0.0" />
  </collision>
 </link>
 <link  name="link45" >
  <inertial >
   <mass  value="0.012499999999999999" />
   <origin  xyz="0.0 0.0 0.020833333333333332" />
  </inertial>
  <visual >
   <geometry >
    <cylinder  length="0.041666666666666664"  radius="0.02" />
   </geometry>
   <origin  xyz="0.0 0.0 0.020833333333333332" />
  </visual>
  <collision >
   <geometry >
    <cylinder  length="0.041666666666666664"  radius="0.02" />
   </geometry>
   <origin  xyz="0.0 0.0 0.020833333333333332" />
  </collision>
 </link>
 <link  name="link46" >
  <inertial >
   <mass  value="0.012499999999999999" />
   <origin  xyz="0.0 0.0 0.0" />
  </inertial>
  <visual >
   <geometry >
    <cylinder  length="0"  radius="0" />
   </geometry>
   <origin  xyz="0.0 0.0 0.0" />
  </visual>
  <collision >
   <geometry >
    <cylinder  length="0"  radius="0" />
   </geometry>
   <origin  xyz="0.0 0.0 0.0" />
  </collision>
 </link>
 <link  name="link47" >
  <inertial >
   <mass  value="0.012499999999999999" />
   <origin  xyz="0.0 0.0 0.020833333333333332" />
  </inertial>
  <visual >
   <geometry >
    <cylinder  length="0.041666666666666664"  radius="0.02" />
   </geometry>
   <origin  xyz="0.0 0.0 0.020833333333333332" />
  </visual>
  <collision >
   <geometry >
    <cylinder  length="0.041666666666666664"  radius="0.02" />
   </geometry>
   <origin  xyz="0.0 0.0 0.020833333333333332" />
  </collision>
 </link>
 <joint  name="joint0"  type="revolute" >
  <parent  link="panda_hand" />
  <child  link="link0" />
  <dynamics  damping="0.0" />
  <axis  xyz="0 1 0" />
  <origin  xyz="0.0 0.0 0" />
 </joint>
 <joint  name="joint1"  type="revolute" >
  <parent  link="link0" />
  <child  link="link1" />
  <dynamics  damping="0.0" />
  <axis  xyz="1 0 0" />
  <origin  xyz="0.0 0.0 0" />
 </joint>
 <joint  name="joint2"  type="revolute" >
  <parent  link="link1" />
  <child  link="link2" />
  <dynamics  damping="0.0" />
  <axis  xyz="0 1 0" />
  <origin  xyz="0.0 0.0 0.041666666666666664" />
 </joint>
 <joint  name="joint3"  type="revolute" >
  <parent  link="link2" />
  <child  link="link3" />
  <dynamics  damping="0.0" />
  <axis  xyz="1 0 0" />
  <origin  xyz="0.0 0.0 0" />
 </joint>
 <joint  name="joint4"  type="revolute" >
  <parent  link="link3" />
  <child  link="link4" />
  <dynamics  damping="0.0" />
  <axis  xyz="0 1 0" />
  <origin  xyz="0.0 0.0 0.041666666666666664" />
 </joint>
 <joint  name="joint5"  type="revolute" >
  <parent  link="link4" />
  <child  link="link5" />
  <dynamics  damping="0.0" />
  <axis  xyz="1 0 0" />
  <origin  xyz="0.0 0.0 0" />
 </joint>
 <joint  name="joint6"  type="revolute" >
  <parent  link="link5" />
  <child  link="link6" />
  <dynamics  damping="0.0" />
  <axis  xyz="0 1 0" />
  <origin  xyz="0.0 0.0 0.041666666666666664" />
 </joint>
 <joint  name="joint7"  type="revolute" >
  <parent  link="link6" />
  <child  link="link7" />
  <dynamics  damping="0.0" />
  <axis  xyz="1 0 0" />
  <origin  xyz="0.0 0.0 0" />
 </joint>
 <joint  name="joint8"  type="revolute" >
  <parent  link="link7" />
  <child  link="link8" />
  <dynamics  damping="0.0" />
  <axis  xyz="0 1 0" />
  <origin  xyz="0.0 0.0 0.041666666666666664" />
 </joint>
 <joint  name="joint9"  type="revolute" >
  <parent  link="link8" />
  <child  link="link9" />
  <dynamics  damping="0.0" />
  <axis  xyz="1 0 0" />
  <origin  xyz="0.0 0.0 0" />
 </joint>
 <joint  name="joint10"  type="revolute" >
  <parent  link="link9" />
  <child  link="link10" />
  <dynamics  damping="0.0" />
  <axis  xyz="0 1 0" />
  <origin  xyz="0.0 0.0 0.041666666666666664" />
 </joint>
 <joint  name="joint11"  type="revolute" >
  <parent  link="link10" />
  <child  link="link11" />
  <dynamics  damping="0.0" />
  <axis  xyz="1 0 0" />
  <origin  xyz="0.0 0.0 0" />
 </joint>
 <joint  name="joint12"  type="revolute" >
  <parent  link="link11" />
  <child  link="link12" />
  <dynamics  damping="0.0" />
  <axis  xyz="0 1 0" />
  <origin  xyz="0.0 0.0 0.041666666666666664" />
 </joint>
 <joint  name="joint13"  type="revolute" >
  <parent  link="link12" />
  <child  link="link13" />
  <dynamics  damping="0.0" />
  <axis  xyz="1 0 0" />
  <origin  xyz="0.0 0.0 0" />
 </joint>
 <joint  name="joint14"  type="revolute" >
  <parent  link="link13" />
  <child  link="link14" />
  <dynamics  damping="0.0" />
  <axis  xyz="0 1 0" />
  <origin  xyz="0.0 0.0 0.041666666666666664" />
 </joint>
 <joint  name="joint15"  type="revolute" >
  <parent  link="link14" />
  <child  link="link15" />
  <dynamics  damping="0.0" />
  <axis  xyz="1 0 0" />
  <origin  xyz="0.0 0.0 0" />
 </joint>
 <joint  name="joint16"  type="revolute" >
  <parent  link="link15" />
  <child  link="link16" />
  <dynamics  damping="0.0" />
  <axis  xyz="0 1 0" />
  <origin  xyz="0.0 0.0 0.041666666666666664" />
 </joint>
 <joint  name="joint17"  type="revolute" >
  <parent  link="link16" />
  <child  link="link17" />
  <dynamics  damping="0.0" />
  <axis  xyz="1 0 0" />
  <origin  xyz="0.0 0.0 0" />
 </joint>
 <joint  name="joint18"  type="revolute" >
  <parent  link="link17" />
  <child  link="link18" />
  <dynamics  damping="0.0" />
  <axis  xyz="0 1 0" />
  <origin  xyz="0.0 0.0 0.041666666666666664" />
 </joint>
 <joint  name="joint19"  type="revolute" >
  <parent  link="link18" />
  <child  link="link19" />
  <dynamics  damping="0.0" />
  <axis  xyz="1 0 0" />
  <origin  xyz="0.0 0.0 0" />
 </joint>
 <joint  name="joint20"  type="revolute" >
  <parent  link="link19" />
  <child  link="link20" />
  <dynamics  damping="0.0" />
  <axis  xyz="0 1 0" />
  <origin  xyz="0.0 0.0 0.041666666666666664" />
 </joint>
 <joint  name="joint21"  type="revolute" >
  <parent  link="link20" />
  <child  link="link21" />
  <dynamics  damping="0.0" />
  <axis  xyz="1 0 0" />
  <origin  xyz="0.0 0.0 0" />
 </joint>
 <joint  name="joint22"  type="revolute" >
  <parent  link="link21" />
  <child  link="link22" />
  <dynamics  damping="0.0" />
  <axis  xyz="0 1 0" />
  <origin  xyz="0.0 0.0 0.041666666666666664" />
 </joint>
 <joint  name="joint23"  type="revolute" >
  <parent  link="link22" />
  <child  link="link23" />
  <dynamics  damping="0.0" />
  <axis  xyz="1 0 0" />
  <origin  xyz="0.0 0.0 0" />
 </joint>
 <joint  name="joint24"  type="revolute" >
  <parent  link="link23" />
  <child  link="link24" />
  <dynamics  damping="0.0" />
  <axis  xyz="0 1 0" />
  <origin  xyz="0.0 0.0 0.041666666666666664" />
 </joint>
 <joint  name="joint25"  type="revolute" >
  <parent  link="link24" />
  <child  link="link25" />
  <dynamics  damping="0.0" />
  <axis  xyz="1 0 0" />
  <origin  xyz="0.0 0.0 0" />
 </joint>
 <joint  name="joint26"  type="revolute" >
  <parent  link="link25" />
  <child  link="link26" />
  <dynamics  damping="0.0" />
  <axis  xyz="0 1 0" />
  <origin  xyz="0.0 0.0 0.041666666666666664" />
 </joint>
 <joint  name="joint27"  type="revolute" >
  <parent  link="link26" />
  <child  link="link27" />
  <dynamics  damping="0.0" />
  <axis  xyz="1 0 0" />
  <origin  xyz="0.0 0.0 0" />
 </joint>
 <joint  name="joint28"  type="revolute" >
  <parent  link="link27" />
  <child  link="link28" />
  <dynamics  damping="0.0" />
  <axis  xyz="0 1 0" />
  <origin  xyz="0.0 0.0 0.041666666666666664" />
 </joint>
 <joint  name="joint29"  type="revolute" >
  <parent  link="link28" />
  <child  link="link29" />
  <dynamics  damping="0.0" />
  <axis  xyz="1 0 0" />
  <origin  xyz="0.0 0.0 0" />
 </joint>
 <joint  name="joint30"  type="revolute" >
  <parent  link="link29" />
  <child  link="link30" />
  <dynamics  damping="0.0" />
  <axis  xyz="0 1 0" />
  <origin  xyz="0.0 0.0 0.041666666666666664" />
 </joint>
 <joint  name="joint31"  type="revolute" >
  <parent  link="link30" />
  <child  link="link31" />
  <dynamics  damping="0.0" />
  <axis  xyz="1 0 0" />
  <origin  xyz="0.0 0.0 0" />
 </joint>
 <joint  name="joint32"  type="revolute" >
  <parent  link="link31" />
  <child  link="link32" />
  <dynamics  damping="0.0" />
  <axis  xyz="0 1 0" />
  <origin  xyz="0.0 0.0 0.041666666666666664" />
 </joint>
 <joint  name="joint33"  type="revolute" >
  <parent  link="link32" />
  <child  link="link33" />
  <dynamics  damping="0.0" />
  <axis  xyz="1 0 0" />
  <origin  xyz="0.0 0.0 0" />
 </joint>
 <joint  name="joint34"  type="revolute" >
  <parent  link="link33" />
  <child  link="link34" />
  <dynamics  damping="0.0" />
  <axis  xyz="0 1 0" />
  <origin  xyz="0.0 0.0 0.041666666666666664" />
 </joint>
 <joint  name="joint35"  type="revolute" >
  <parent  link="link34" />
  <child  link="link35" />
  <dynamics  damping="0.0" />
  <axis  xyz="1 0 0" />
  <origin  xyz="0.0 0.0 0" />
 </joint>
 <joint  name="joint36"  type="revolute" >
  <parent  link="link35" />
  <child  link="link36" />
  <dynamics  damping="0.0" />
  <axis  xyz="0 1 0" />
  <origin  xyz="0.0 0.0 0.041666666666666664" />
 </joint>
 <joint  name="joint37"  type="revolute" >
  <parent  link="link36" />
  <child  link="link37" />
  <dynamics  damping="0.0" />
  <axis  xyz="1 0 0" />
  <origin  xyz="0.0 0.0 0" />
 </joint>
 <joint  name="joint38"  type="revolute" >
  <parent  link="link37" />
  <child  link="link38" />
  <dynamics  damping="0.0" />
  <axis  xyz="0 1 0" />
  <origin  xyz="0.0 0.0 0.041666666666666664" />
 </joint>
 <joint  name="joint39"  type="revolute" >
  <parent  link="link38" />
  <child  link="link39" />
  <dynamics  damping="0.0" />
  <axis  xyz="1 0 0" />
  <origin  xyz="0.0 0.0 0" />
 </joint>
 <joint  name="joint40"  type="revolute" >
  <parent  link="link39" />
  <child  link="link40" />
  <dynamics  damping="0.0" />
  <axis  xyz="0 1 0" />
  <origin  xyz="0.0 0.0 0.041666666666666664" />
 </joint>
 <joint  name="joint41"  type="revolute" >
  <parent  link="link40" />
  <child  link="link41" />
  <dynamics  damping="0.0" />
  <axis  xyz="1 0 0" />
  <origin  xyz="0.0 0.0 0" />
 </joint>
 <joint  name="joint42"  type="revolute" >
  <parent  link="link41" />
  <child  link="link42" />
  <dynamics  damping="0.0" />
  <axis  xyz="0 1 0" />
  <origin  xyz="0.0 0.0 0.041666666666666664" />
 </joint>
 <joint  name="joint43"  type="revolute" >
  <parent  link="link42" />
  <child  link="link43" />
  <dynamics  damping="0.0" />
  <axis  xyz="1 0 0" />
  <origin  xyz="0.0 0.0 0" />
 </joint>
 <joint  name="joint44"  type="revolute" >
  <parent  link="link43" />
  <child  link="link44" />
  <dynamics  damping="0.0" />
  <axis  xyz="0 1 0" />
  <origin  xyz="0.0 0.0 0.041666666666666664" />
 </joint>
 <joint  name="joint45"  type="revolute" >
  <parent  link="link44" />
  <child  link="link45" />
  <dynamics  damping="0.0" />
  <axis  xyz="1 0 0" />
  <origin  xyz="0.0 0.0 0" />
 </joint>
 <joint  name="joint46"  type="revolute" >
  <parent  link="link45" />
  <child  link="link46" />
  <dynamics  damping="0.0" />
  <axis  xyz="0 1 0" />
  <origin  xyz="0.0 0.0 0.041666666666666664" />
 </joint>
 <joint  name="joint47"  type="revolute" >
  <parent  link="link46" />
  <child  link="link47" />
  <dynamics  damping="0.0" />
  <axis  xyz="1 0 0" />
  <origin  xyz="0.0 0.0 0" />
 </joint>
</robot>


